<?xml version="1.0"?>
<!-- created with Phobos 0.7 -->
  <robot name="hand">

    <link name="arm0">
      <inertial>
        <origin xyz="0.00575 0.0098 0.78821" rpy="0 0 0"/>
        <mass value="0.1"/>
        <inertia ixx="0.0872" ixy="0" ixz="0" iyy="0.001" iyz="0" izz="0.20686"/>
      </inertial>
      <visual name="visual_arm0">
        <origin xyz="0.00575 0.0098 0.78821" rpy="0 0 0"/>
        <geometry>
          <mesh filename="../meshes/obj/arm0_mesh.obj" scale="3.37757 1.0 5.67104"/>
        </geometry>
      </visual>
      <collision name="collision_arm0">
        <origin xyz="0.00575 0.0098 0.78334" rpy="0 0 0"/>
        <geometry>
          <mesh filename="../meshes/obj/arm0_mesh.obj" scale="1.0 1.0 1.60549"/>
        </geometry>
      </collision>
    </link>

    <link name="arm1">
      <inertial>
        <origin xyz="-0.00401 0.0098 0.68658" rpy="0 0 0"/>
        <mass value="0.1"/>
        <inertia ixx="0.0872" ixy="0" ixz="0" iyy="0.001" iyz="0" izz="0.20686"/>
      </inertial>
      <visual name="visual_arm1">
        <origin xyz="-0.00401 0.0098 0.68658" rpy="0 0 0"/>
        <geometry>
          <mesh filename="../meshes/obj/arm1_mesh.obj" scale="3.37757 1.0 5.67104"/>
        </geometry>
      </visual>
      <collision name="collision_arm1">
        <origin xyz="-0.00401 0.0098 0.68171" rpy="0 0 0"/>
        <geometry>
          <mesh filename="../meshes/obj/arm1_mesh.obj" scale="1.0 1.0 1.60549"/>
        </geometry>
      </collision>
    </link>

    <link name="arm_base">
      <inertial>
        <origin xyz="0.00575 0.0098 0.78821" rpy="0 0 0"/>
        <mass value="0.1"/>
        <inertia ixx="0.0872" ixy="0" ixz="0" iyy="0.001" iyz="0" izz="0.20686"/>
      </inertial>
      <visual name="visual_arm_base">
        <origin xyz="0.00575 0.0098 0.78821" rpy="0 0 0"/>
        <geometry>
          <mesh filename="../meshes/obj/arm_base_mesh.obj" scale="3.37757 1.0 5.67104"/>
        </geometry>
      </visual>
      <collision name="collision_arm_base">
        <origin xyz="0.00575 0.0098 0.78334" rpy="0 0 0"/>
        <geometry>
          <mesh filename="../meshes/obj/arm_base_mesh.obj" scale="1.0 1.0 1.60549"/>
        </geometry>
      </collision>
    </link>

    <link name="base">
      <inertial>
        <origin xyz="0.00137 0.00576 -0.00922" rpy="0 0 0"/>
        <mass value="0"/>
        <inertia ixx="0.0039" ixy="0" ixz="0" iyy="0.00453" iyz="0" izz="0.00457"/>
      </inertial>
      <visual name="base_visual">
        <origin xyz="0.00137 0.00576 -0.00922" rpy="0 0 0"/>
        <geometry>
          <box size="0.55837 0.48681 0.48115"/>
        </geometry>
      </visual>
      <collision name="base_collision">
        <origin xyz="0.00137 0.00576 -0.00922" rpy="0 0 0"/>
        <geometry>
          <mesh filename="../meshes/obj/base_mesh.obj" scale="1.0 1.0 1.0"/>
        </geometry>
      </collision>
    </link>

    <link name="index0">
      <inertial>
        <origin xyz="0 0.00067 0.00103" rpy="0 0 0"/>
        <mass value="0.1"/>
        <inertia ixx="0.03658" ixy="0" ixz="0" iyy="0.03658" iyz="0" izz="0.03658"/>
      </inertial>
      <visual name="visual_index0">
        <origin xyz="0 0.00067 0.00103" rpy="0 0 0"/>
        <geometry>
          <mesh filename="../meshes/obj/index0_mesh.obj" scale="1.0 1.0 1.0"/>
        </geometry>
      </visual>
      <collision name="collision_index0">
        <origin xyz="0 0.00067 0.00103" rpy="0 0 0"/>
        <geometry>
          <box size="0.0703 0.07139 0.07181"/>
        </geometry>
      </collision>
    </link>

    <link name="index1">
      <inertial>
        <origin xyz="0.00139 0 0.14195" rpy="0 0 0"/>
        <mass value="0.1"/>
        <inertia ixx="0.08761" ixy="0" ixz="0" iyy="0.08761" iyz="0" izz="0.03354"/>
      </inertial>
      <visual name="visual_index1">
        <origin xyz="0.00139 0 0.14195" rpy="0 0 0"/>
        <geometry>
          <mesh filename="../meshes/obj/index1_mesh.obj" scale="1.0 1.0 1.0"/>
        </geometry>
      </visual>
      <collision name="collision_index1">
        <origin xyz="0.00139 0 0.14195" rpy="0 0 0"/>
        <geometry>
          <box size="0.14118 0.12254 0.28672"/>
        </geometry>
      </collision>
    </link>

    <link name="index2">
      <inertial>
        <origin xyz="0.00032 0 0.09946" rpy="0 0 0"/>
        <mass value="0.1"/>
        <inertia ixx="0.08761" ixy="0" ixz="0" iyy="0.08761" iyz="0" izz="0.03354"/>
      </inertial>
      <visual name="visual_index2">
        <origin xyz="0.00032 0 0.09946" rpy="0 0 0"/>
        <geometry>
          <mesh filename="../meshes/obj/index2_mesh.obj" scale="1.0 1.0 1.0"/>
        </geometry>
      </visual>
      <collision name="collision_index2">
        <origin xyz="0.00032 0 0.09946" rpy="0 0 0"/>
        <geometry>
          <box size="0.14118 0.12254 0.27643"/>
        </geometry>
      </collision>
    </link>

    <link name="index3">
      <inertial>
        <origin xyz="0.00115 0 0.10044" rpy="0 0 0"/>
        <mass value="0.1"/>
        <inertia ixx="0.08761" ixy="0" ixz="0" iyy="0.08761" iyz="0" izz="0.03354"/>
      </inertial>
      <visual name="visual_index3">
        <origin xyz="0.00115 0 0.10044" rpy="0 0 0"/>
        <geometry>
          <mesh filename="../meshes/obj/index3_mesh.obj" scale="1.0 1.0 1.0"/>
        </geometry>
      </visual>
      <collision name="collision_index3">
        <origin xyz="0.00115 0 0.10044" rpy="0 0 0"/>
        <geometry>
          <box size="0.14118 0.12254 0.28086"/>
        </geometry>
      </collision>
    </link>

    <link name="little0">
      <inertial>
        <origin xyz="0 0.00231 -0.00092" rpy="0 0 0"/>
        <mass value="0.1"/>
        <inertia ixx="0.03658" ixy="0" ixz="0" iyy="0.03658" iyz="0" izz="0.03658"/>
      </inertial>
      <visual name="visual_little0">
        <origin xyz="0 0.00231 -0.00092" rpy="0 0 0"/>
        <geometry>
          <mesh filename="../meshes/obj/little0_mesh.obj" scale="1.0 1.0 1.0"/>
        </geometry>
      </visual>
      <collision name="collision_little0">
        <origin xyz="0 0.00231 -0.00092" rpy="0 0 0"/>
        <geometry>
          <box size="0.07071 0.07112 0.07181"/>
        </geometry>
      </collision>
    </link>

    <link name="little1">
      <inertial>
        <origin xyz="0.00056 0 0.12158" rpy="0 0 0"/>
        <mass value="0.1"/>
        <inertia ixx="0.08761" ixy="0" ixz="0" iyy="0.08761" iyz="0" izz="0.03354"/>
      </inertial>
      <visual name="visual_little1">
        <origin xyz="0.00056 0 0.12158" rpy="0 0 0"/>
        <geometry>
          <mesh filename="../meshes/obj/little1_mesh.obj" scale="1.0 1.0 1.0"/>
        </geometry>
      </visual>
      <collision name="collision_little1">
        <origin xyz="0.00056 0 0.12158" rpy="0 0 0"/>
        <geometry>
          <box size="0.1411 0.1246 0.26256"/>
        </geometry>
      </collision>
    </link>

    <link name="little2">
      <inertial>
        <origin xyz="-0.0035 0 0.07948" rpy="0 0 0"/>
        <mass value="0.1"/>
        <inertia ixx="0.08761" ixy="0" ixz="0" iyy="0.08761" iyz="0" izz="0.03354"/>
      </inertial>
      <visual name="visual_little2">
        <origin xyz="-0.0035 0 0.07948" rpy="0 0 0"/>
        <geometry>
          <mesh filename="../meshes/obj/little2_mesh.obj" scale="1.0 1.0 1.0"/>
        </geometry>
      </visual>
      <collision name="collision_little2">
        <origin xyz="-0.0035 0 0.07948" rpy="0 0 0"/>
        <geometry>
          <box size="0.1411 0.1246 0.25314"/>
        </geometry>
      </collision>
    </link>

    <link name="little3">
      <inertial>
        <origin xyz="-0.0029 0 0.10009" rpy="0 0 0"/>
        <mass value="0.1"/>
        <inertia ixx="0.08761" ixy="0" ixz="0" iyy="0.08761" iyz="0" izz="0.03354"/>
      </inertial>
      <visual name="visual_little3">
        <origin xyz="-0.0029 0 0.10009" rpy="0 0 0"/>
        <geometry>
          <mesh filename="../meshes/obj/little3_mesh.obj" scale="1.0 1.0 1.0"/>
        </geometry>
      </visual>
      <collision name="collision_little3">
        <origin xyz="-0.0029 0 0.10009" rpy="0 0 0"/>
        <geometry>
          <box size="0.1411 0.1246 0.2572"/>
        </geometry>
      </collision>
    </link>

    <link name="middle0">
      <inertial>
        <origin xyz="0 0.00229 1e-05" rpy="0 0 0"/>
        <mass value="0.1"/>
        <inertia ixx="0.03658" ixy="0" ixz="0" iyy="0.03658" iyz="0" izz="0.03658"/>
      </inertial>
      <visual name="visual_middle0">
        <origin xyz="0 0.00229 1e-05" rpy="0 0 0"/>
        <geometry>
          <mesh filename="../meshes/obj/middle0_mesh.obj" scale="1.0 1.0 1.0"/>
        </geometry>
      </visual>
      <collision name="collision_middle0">
        <origin xyz="0 0.00229 1e-05" rpy="0 0 0"/>
        <geometry>
          <box size="0.06979 0.0716 0.07181"/>
        </geometry>
      </collision>
    </link>

    <link name="middle1">
      <inertial>
        <origin xyz="0.00355 0 0.18008" rpy="0 0 0"/>
        <mass value="0.1"/>
        <inertia ixx="0.08761" ixy="0" ixz="0" iyy="0.08761" iyz="0" izz="0.03354"/>
      </inertial>
      <visual name="visual_middle1">
        <origin xyz="0.00355 0 0.18008" rpy="0 0 0"/>
        <geometry>
          <mesh filename="../meshes/obj/middle1_mesh.obj" scale="1.0 1.0 1.0"/>
        </geometry>
      </visual>
      <collision name="collision_middle1">
        <origin xyz="0.00355 0 0.18008" rpy="0 0 0"/>
        <geometry>
          <box size="0.14113 0.12421 0.3451"/>
        </geometry>
      </collision>
    </link>

    <link name="middle2">
      <inertial>
        <origin xyz="-0.00181 0 0.1154" rpy="0 0 0"/>
        <mass value="0.1"/>
        <inertia ixx="0.08761" ixy="0" ixz="0" iyy="0.08761" iyz="0" izz="0.03354"/>
      </inertial>
      <visual name="visual_middle2">
        <origin xyz="-0.00181 0 0.1154" rpy="0 0 0"/>
        <geometry>
          <mesh filename="../meshes/obj/middle2_mesh.obj" scale="1.0 1.0 1.0"/>
        </geometry>
      </visual>
      <collision name="collision_middle2">
        <origin xyz="-0.00181 0 0.1154" rpy="0 0 0"/>
        <geometry>
          <box size="0.14113 0.12421 0.33272"/>
        </geometry>
      </collision>
    </link>

    <link name="middle3">
      <inertial>
        <origin xyz="-0.00957 0 0.12562" rpy="0 0 0"/>
        <mass value="0.1"/>
        <inertia ixx="0.08761" ixy="0" ixz="0" iyy="0.08761" iyz="0" izz="0.03354"/>
      </inertial>
      <visual name="visual_middle3">
        <origin xyz="-0.00957 0 0.12562" rpy="0 0 0"/>
        <geometry>
          <mesh filename="../meshes/obj/middle3_mesh.obj" scale="1.0 1.0 1.0"/>
        </geometry>
      </visual>
      <collision name="collision_middle3">
        <origin xyz="-0.00957 0 0.12562" rpy="0 0 0"/>
        <geometry>
          <box size="0.14113 0.12421 0.33806"/>
        </geometry>
      </collision>
    </link>

    <link name="palm">
      <inertial>
        <origin xyz="-0.02337 0.00552 0.35053" rpy="0 0 0"/>
        <mass value="0.1"/>
        <inertia ixx="0.5848" ixy="0.00688" ixz="-0.02387" iyy="1.3842" iyz="0.00057" izz="0.86652"/>
      </inertial>
      <visual name="visual_palm">
        <origin xyz="-0.02489 0.00224 0.3494" rpy="0 0 0"/>
        <geometry>
          <mesh filename="../meshes/obj/palm_mesh.obj" scale="1.0 1.0 1.0"/>
        </geometry>
        <material name="Material"/>
      </visual>
      <collision name="collision_palm">
        <origin xyz="-0.0236 0.00224 0.35176" rpy="0 0 0"/>
        <geometry>
          <box size="0.82991 0.15132 0.65196"/>
        </geometry>
      </collision>
    </link>

    <link name="ring0">
      <inertial>
        <origin xyz="0 0.00229 1e-05" rpy="0 0 0"/>
        <mass value="0.1"/>
        <inertia ixx="0.03658" ixy="0" ixz="0" iyy="0.03658" iyz="0" izz="0.03658"/>
      </inertial>
      <visual name="visual_ring0">
        <origin xyz="0 0.00229 1e-05" rpy="0 0 0"/>
        <geometry>
          <mesh filename="../meshes/obj/ring0_mesh.obj" scale="1.0 1.0 1.0"/>
        </geometry>
      </visual>
      <collision name="collision_ring0">
        <origin xyz="0 0.00229 1e-05" rpy="0 0 0"/>
        <geometry>
          <box size="0.06979 0.0716 0.07181"/>
        </geometry>
      </collision>
    </link>

    <link name="ring1">
      <inertial>
        <origin xyz="0.00105 0 0.15453" rpy="0 0 0"/>
        <mass value="0.1"/>
        <inertia ixx="0.08761" ixy="0" ixz="0" iyy="0.08761" iyz="0" izz="0.03354"/>
      </inertial>
      <visual name="visual_ring1">
        <origin xyz="0.00105 0 0.15453" rpy="0 0 0"/>
        <geometry>
          <mesh filename="../meshes/obj/ring1_mesh.obj" scale="1.0 1.0 1.0"/>
        </geometry>
      </visual>
      <collision name="collision_ring1">
        <origin xyz="0.00105 0 0.15453" rpy="0 0 0"/>
        <geometry>
          <box size="0.14113 0.12421 0.33299"/>
        </geometry>
      </collision>
    </link>

    <link name="ring2">
      <inertial>
        <origin xyz="-0.00181 0 0.11135" rpy="0 0 0"/>
        <mass value="0.1"/>
        <inertia ixx="0.08761" ixy="0" ixz="0" iyy="0.08761" iyz="0" izz="0.03354"/>
      </inertial>
      <visual name="visual__ring2">
        <origin xyz="-0.00181 0 0.11135" rpy="0 0 0"/>
        <geometry>
          <mesh filename="../meshes/obj/ring2_mesh.obj" scale="1.0 1.0 1.0"/>
        </geometry>
      </visual>
      <collision name="collision__ring2">
        <origin xyz="-0.00181 0 0.11135" rpy="0 0 0"/>
        <geometry>
          <box size="0.14113 0.12421 0.32105"/>
        </geometry>
      </collision>
    </link>

    <link name="ring3">
      <inertial>
        <origin xyz="-0.00957 0 0.12121" rpy="0 0 0"/>
        <mass value="0.1"/>
        <inertia ixx="0.08761" ixy="0" ixz="0" iyy="0.08761" iyz="0" izz="0.03354"/>
      </inertial>
      <visual name="visual_ring3">
        <origin xyz="-0.00957 0 0.12121" rpy="0 0 0"/>
        <geometry>
          <mesh filename="../meshes/obj/ring3_mesh.obj" scale="1.0 1.0 1.0"/>
        </geometry>
      </visual>
      <collision name="collision__ring3">
        <origin xyz="-0.00957 0 0.12121" rpy="0 0 0"/>
        <geometry>
          <box size="0.14113 0.12421 0.3262"/>
        </geometry>
      </collision>
    </link>

    <link name="thumb0">
      <inertial>
        <origin xyz="-0.0002 -0.00056 8e-05" rpy="0 0 0"/>
        <mass value="0.1"/>
        <inertia ixx="0.03658" ixy="0" ixz="0" iyy="0.03658" iyz="0" izz="0.03658"/>
      </inertial>
      <visual name="visual_thumb0">
        <origin xyz="-0.0002 -0.00056 8e-05" rpy="0 0 0"/>
        <geometry>
          <mesh filename="../meshes/obj/thumb0_mesh.obj" scale="1.0 1.0 1.0"/>
        </geometry>
      </visual>
      <collision name="collision_thumb0">
        <origin xyz="-0.0002 -0.00056 8e-05" rpy="0 0 0"/>
        <geometry>
          <box size="0.07171 0.07151 0.06987"/>
        </geometry>
      </collision>
    </link>

    <link name="thumb1">
      <inertial>
        <origin xyz="-0.10141 0.00337 0.00732" rpy="0 0 0"/>
        <mass value="0.1"/>
        <inertia ixx="0.08761" ixy="0" ixz="0" iyy="0.08761" iyz="0" izz="0.03354"/>
      </inertial>
      <visual name="visual_thumb1">
        <origin xyz="-0.10141 0.00337 0.00732" rpy="0 0 0"/>
        <geometry>
          <mesh filename="../meshes/obj/thumb1_mesh.obj" scale="1.0 1.0 1.0"/>
        </geometry>
      </visual>
      <collision name="collision_thumb1">
        <origin xyz="-0.10141 0.00337 0.00732" rpy="0 0 0"/>
        <geometry>
          <box size="0.21098 0.12737 0.14617"/>
        </geometry>
      </collision>
    </link>

    <link name="thumb2">
      <inertial>
        <origin xyz="-0.07785 0.00265 0.00842" rpy="0 0 0"/>
        <mass value="0.1"/>
        <inertia ixx="0.08761" ixy="0" ixz="0" iyy="0.08761" iyz="0" izz="0.03354"/>
      </inertial>
      <visual name="visual_thumb2">
        <origin xyz="-0.07785 0.00265 0.00842" rpy="0 0 0"/>
        <geometry>
          <mesh filename="../meshes/obj/thumb2_mesh.obj" scale="1.0 1.0 1.0"/>
        </geometry>
      </visual>
      <collision name="collision_thumb2">
        <origin xyz="-0.07785 0.00265 0.00842" rpy="0 0 0"/>
        <geometry>
          <box size="0.20341 0.12723 0.14599"/>
        </geometry>
      </collision>
    </link>

    <link name="thumb3">
      <inertial>
        <origin xyz="-0.07916 0.00252 0.00105" rpy="0 0 0"/>
        <mass value="0.1"/>
        <inertia ixx="0.08761" ixy="0" ixz="0" iyy="0.08761" iyz="0" izz="0.03354"/>
      </inertial>
      <visual name="visual_thumb3">
        <origin xyz="-0.07916 0.00252 0.00105" rpy="0 0 0"/>
        <geometry>
          <mesh filename="../meshes/obj/thumb3_mesh.obj" scale="1.0 1.0 1.0"/>
        </geometry>
      </visual>
      <collision name="collision_thumb3">
        <origin xyz="-0.07916 0.00252 0.00105" rpy="0 0 0"/>
        <geometry>
          <box size="0.20779 0.12731 0.14609"/>
        </geometry>
      </collision>
    </link>

    <joint name="arm0" type="revolute">
      <origin xyz="0.00139 0.02077 1.53803" rpy="1.57582 0.00091 -0.0009"/>
      <parent link="arm_base"/>
      <child link="arm0"/>
      <axis xyz="0.99993 0 -0.01224"/>
      <limit lower="-3.14" upper="3.14" effort="300.0" velocity="1.0"/>
    </joint>

    <joint name="arm1" type="revolute">
      <origin xyz="0.01101 0 1.48559" rpy="0 0 0"/>
      <parent link="arm0"/>
      <child link="arm1"/>
      <axis xyz="0.99999 0 -0.00502"/>
      <limit lower="-3.14" upper="3.14" effort="300.0" velocity="1.0"/>
    </joint>

    <joint name="arm_base" type="revolute">
      <origin xyz="-0.00266 0.00425 0.26499" rpy="0.00038 -0.0009 0"/>
      <parent link="base"/>
      <child link="arm_base"/>
      <axis xyz="-0.00483 0.00039 0.99999"/>
      <limit lower="-3.14" upper="3.14" effort="300.0" velocity="1.0"/>
    </joint>

    <joint name="index0" type="revolute">
      <origin xyz="-0.39131 -0.00128 0.59296" rpy="0 -0.026 0"/>
      <parent link="palm"/>
      <child link="index0"/>
      <axis xyz="0 -0.99997 0.00709"/>
      <limit lower="-3.14" upper="3.14" effort="300.0" velocity="1.0"/>
    </joint>

    <joint name="index1" type="revolute">
      <origin xyz="0.0001 -0.00253 -0.01509" rpy="0 0 0"/>
      <parent link="index0"/>
      <child link="index1"/>
      <axis xyz="0.99997 0 0.00733"/>
      <limit lower="-3.14" upper="3.14" effort="300.0" velocity="1.0"/>
    </joint>

    <joint name="index2" type="revolute">
      <origin xyz="0.00339 0.00133 0.24319" rpy="0 0 0"/>
      <parent link="index1"/>
      <child link="index2"/>
      <axis xyz="0.99999 0 0.0048"/>
      <limit lower="-3.14" upper="3.14" effort="300.0" velocity="1.0"/>
    </joint>

    <joint name="index3" type="revolute">
      <origin xyz="0.00233 0.00181 0.19844" rpy="0 0 0"/>
      <parent link="index2"/>
      <child link="index3"/>
      <axis xyz="0.99993 0 -0.01203"/>
      <limit lower="-3.14" upper="3.14" effort="300.0" velocity="1.0"/>
    </joint>

    <joint name="little0" type="revolute">
      <origin xyz="0.3165 -0.00289 0.61751" rpy="0 0 0"/>
      <parent link="palm"/>
      <child link="little0"/>
      <axis xyz="0 -0.99999 0.00543"/>
      <limit lower="-3.14" upper="3.14" effort="300.0" velocity="1.0"/>
    </joint>

    <joint name="little1" type="revolute">
      <origin xyz="3e-05 -0.00086 0.00323" rpy="0 0 0"/>
      <parent link="little0"/>
      <child link="little1"/>
      <axis xyz="0.99988 0 -0.01517"/>
      <limit lower="-3.14" upper="3.14" effort="300.0" velocity="1.0"/>
    </joint>

    <joint name="little2" type="revolute">
      <origin xyz="0.00225 0.00126 0.20289" rpy="0 0 0"/>
      <parent link="little1"/>
      <child link="little2"/>
      <axis xyz="0.99976 0 0.02175"/>
      <limit lower="-3.14" upper="3.14" effort="300.0" velocity="1.0"/>
    </joint>

    <joint name="little3" type="revolute">
      <origin xyz="0.00261 0.00171 0.14934" rpy="0 0 0"/>
      <parent link="little2"/>
      <child link="little3"/>
      <axis xyz="0.9998 0 0.02006"/>
      <limit lower="-3.14" upper="3.14" effort="300.0" velocity="1.0"/>
    </joint>

    <joint name="middle0" type="revolute">
      <origin xyz="-0.14136 -0.00293 0.63492" rpy="0 0 0"/>
      <parent link="palm"/>
      <child link="middle0"/>
      <axis xyz="0 -1.0 -0.00025"/>
      <limit lower="-3.14" upper="3.14" effort="300.0" velocity="1.0"/>
    </joint>

    <joint name="middle1" type="revolute">
      <origin xyz="-0.00235 -0.00096 0.00774" rpy="0 0 0"/>
      <parent link="middle0"/>
      <child link="middle1"/>
      <axis xyz="0.99992 0 -0.01259"/>
      <limit lower="-3.14" upper="3.14" effort="300.0" velocity="1.0"/>
    </joint>

    <joint name="middle2" type="revolute">
      <origin xyz="0.00765 0.0014 0.29592" rpy="0 0 0"/>
      <parent link="middle1"/>
      <child link="middle2"/>
      <axis xyz="0.99981 0 -0.01974"/>
      <limit lower="-3.14" upper="3.14" effort="300.0" velocity="1.0"/>
    </joint>

    <joint name="middle3" type="revolute">
      <origin xyz="0.01086 0.00191 0.22772" rpy="0 0 0"/>
      <parent link="middle2"/>
      <child link="middle3"/>
      <axis xyz="0.99891 0 -0.04675"/>
      <limit lower="-3.14" upper="3.14" effort="300.0" velocity="1.0"/>
    </joint>

    <joint name="palm" type="revolute">
      <origin xyz="-0.01412 -0.00489 1.41271" rpy="0 0.0007 0"/>
      <parent link="arm1"/>
      <child link="palm"/>
      <axis xyz="0.99795 -0.06295 0.01168"/>
      <limit lower="-3.14" upper="3.14" effort="300.0" velocity="1.0"/>
    </joint>

    <joint name="ring0" type="revolute">
      <origin xyz="0.08147 -0.00293 0.64689" rpy="0 0 0"/>
      <parent link="palm"/>
      <child link="ring0"/>
      <axis xyz="0 -1.0 -0.00025"/>
      <limit lower="-3.14" upper="3.14" effort="300.0" velocity="1.0"/>
    </joint>

    <joint name="ring1" type="revolute">
      <origin xyz="-0.00235 -0.00096 0.00774" rpy="0 0 0"/>
      <parent link="ring0"/>
      <child link="ring1"/>
      <axis xyz="0.99992 0 -0.01259"/>
      <limit lower="-3.14" upper="3.14" effort="300.0" velocity="1.0"/>
    </joint>

    <joint name="ring2" type="revolute">
      <origin xyz="0.00514 0.0014 0.26631" rpy="0 0 0"/>
      <parent link="ring1"/>
      <child link="ring2"/>
      <axis xyz="0.99982 0 -0.01904"/>
      <limit lower="-3.14" upper="3.14" effort="300.0" velocity="1.0"/>
    </joint>

    <joint name="ring3" type="revolute">
      <origin xyz="0.01086 0.00191 0.21972" rpy="0 0 0"/>
      <parent link="ring2"/>
      <child link="ring3"/>
      <axis xyz="0.99898 0 -0.04511"/>
      <limit lower="-3.14" upper="3.14" effort="300.0" velocity="1.0"/>
    </joint>

    <joint name="thumb0" type="revolute">
      <origin xyz="-0.41455 -0.00202 0.3021" rpy="0 0 0"/>
      <parent link="palm"/>
      <child link="thumb0"/>
      <axis xyz="0.08899 0.99379 0.06681"/>
      <limit lower="-3.14" upper="3.14" effort="300.0" velocity="1.0"/>
    </joint>

    <joint name="thumb1" type="revolute">
      <origin xyz="-0.03203 0.00364 -0.00016" rpy="0 0 0"/>
      <parent link="thumb0"/>
      <child link="thumb1"/>
      <axis xyz="-0.02687 -0.02285 -0.99938"/>
      <limit lower="-3.14" upper="3.14" effort="300.0" velocity="1.0"/>
    </joint>

    <joint name="thumb2" type="revolute">
      <origin xyz="-0.17578 0.00434 0.00565" rpy="0 0 0"/>
      <parent link="thumb1"/>
      <child link="thumb2"/>
      <axis xyz="-0.06485 -0.02161 -0.99766"/>
      <limit lower="-3.14" upper="3.14" effort="300.0" velocity="1.0"/>
    </joint>

    <joint name="thumb3" type="revolute">
      <origin xyz="-0.14642 0.00318 0.01587" rpy="0 0 0"/>
      <parent link="thumb2"/>
      <child link="thumb3"/>
      <axis xyz="-0.01701 -0.02316 -0.99959"/>
      <limit lower="-3.14" upper="3.14" effort="300.0" velocity="1.0"/>
    </joint>

    <material name="Material">
      <color rgba="0.64 0.64 0.64 1.0"/>
    </material>

  </robot>
